Workbook

Sheet Export Summary
B3: This document was exported from Numbers. Each table was converted to an Excel worksheet. All other objects on each Numbers sheet were placed on separate worksheets. Please be aware that formula calculations may differ in Excel.
B7: Numbers Sheet Name | C7: Numbers Table Name | D7: Excel Worksheet Name
B9: BL
C10: Table 1 | D10: BL
B11: PC
C12: Table 1 | D12: PC
B13: WesternTerrace
C14: Table 1 | D14: WesternTerrace
B15: North Rd
C16: Table 1 | D16: North Rd
B17: Lincoln Circus
C18: Table 1 | D18: Lincoln Circus
B19: newcastlecircus
C20: Table 1 | D20: newcastlecircus
B21: Park Drive
C22: Table 1 | D22: Park Drive
B23: Peveril Drive
C24: Table 1 | D24: Peveril Drive
B25: lentonave-dan
C26: Table 1 | D26: lentonave-dan
B27: Clumber rd W dan
C28: Table 1 | D28: Clumber rd W dan
B29: maxtoke rd dan
C30: Table 1 | D30: maxtoke rd dan
B31: clumbercress dan
C32: Table 1 | D32: clumbercress dan
B33: Cav cresn
C34: Table 1 | D34: Cav cresn
B35: southrd p 168
C36: Table 1 | D36: southrd p 168
B37: Cavendish Cres S p182
C38: Table 1 | D38: Cavendish Cres S p182
B39: holles cres p202
C40: Table 1 | D40: holles cres p202
B41: LentonRd p208
C42: Table 1 | D42: LentonRd p208
B43: Hermitage Walkp 256
C44: Table 1 | D44: Hermitage Walkp 256
B45: Kenilworthrd p 259
C46: Table 1 | D46: Kenilworthrd p 259
...

Sheet BL
A1: House ID | B1: House Name | C1: NO. | D1: Address | E1: Family | F1: Name | G1: W/M/G/B | K1: Relationship to Head of family | Q1: Age | R1: Married/Single/Widow er | U1: Married yrs | V1: Children born | W1: children living | X1: Personal Occupation | Y1: Industry | Z1: Economic Participants | AA1: Employer/worker | AC1: Born
G2: W | H2: M | I2: G | J2: B | K2: HEAD women head | L2: WIFE | M2: daughter | N2: son | O2: Other | P2: Servant | R2: M | S2: S | T2: W | AA2: Employer | AB2: Worker | AC2: Nottinghamshire
A3: BL1 | C3: 10 | D3: Barrack Lane | E3: Derry | F3: George | H3: 1 | K3: 1 | Q3: 65 | R3: 1 | X3: Jobbing Gardener | Z3: 1 | AB3: 1 | AC3: 1
A4: BL1 | C4: 10 | D4: Barrack Lane | E4: Derry | F4: Sarah | G4: 1 | L4: 1 | Q4: 58 | R4: 1 | U4: 28 | V4: 4 | W4: 4 | AD4: Leicester
A5: BL1 | C5: 10 | D5: Barrack Lane | E5: Derry | F5: George | H5: 1 | N5: 1 | Q5: 18 | S5: 1 | X5: Warper | Y5: Incandesent Mantle | Z5: 1 | AB5: 1 | AC5: 1
A6: BL1 | C6: 10 | D6: barrack Lane | E6: derry | F6: Elizabeth | G6: 1 | M6: 1 | Q6: 26 | S6: 1 | X6: Domestic help | Z6: 1 | AB6: 1 | AC6: 1
A7: BL1 | C7: 10 | D7: Barrack Lane | E7: Derry | F7: Annie | G7: 1 | M7: 1 | Q7: 15 | S7: 1 | X7: Tailoress (Seamstress) | Z7: 1 | AB7: 1 | AC7: 1
A8: BL1 | C8: 10 | D8: Barrack Lane | E8: Derry | F8: Mabel Sarah | I8: 1 | O8: grand daugher | Q8: 7 | R8: - | S8: - | X8: child | AC8: 1
A9: BL2 | B9: Barrack Yard | D9: Barrack Lane | E9: Baker | F9: Elizabeth | G9: 1 | K9: 1 | Q9: 81 | T9: 1 | V9: 1 | W9: 1 | AC9: 1
A10: BL2 | B10: Barrack Yard | D10: Barrack Lane | E10: Smith | F10: Arthur William | H10: 1 | O10: Son in law | Q10: 42 | R10: 1 | X10: Cabinet maker | Y10: House furnisher | Z10: 1 | AB10: 1 | AC10: 1
A11: BL2 | B11: Barrack Yard | D11: Barrack Lane | E11: Smith | F11: Elizabeth Ann | G11: 1 | M11: 1 | Q11: 43 | R11: 1 | U11: 16 | V11: 0 | W11: 0 | AC11: 1
A12: BL3 | B12: Barrack Yard | D12: Barrack Lane | E12: Blythe | F12: Joseph | H12: 1 | K12: 1 | Q12: 50 | R12: 1 | X12: Sexton | Y12: Parish Church | Z12: 1 | AB12: 1 | AD12: Lincolnshire
A13: BL3 | B13: Barrack Yard | D13: Barrack Lane | E13: Blythe | F13: Annie | G13: 1 | L13: 1 | Q13: 48 | R13: 1 | U13: 18 | V13: 3 | W13: 3 | AD13: Yorkshire
A14: BL3 | B14: Barrack Yard | D14: Barrack Lane | E14: Blythe | F14: Marjorie | G14: 1 | M14: 1 | Q14: 15 | S14: 1 | X14: Typist | Y14: lace warehouse | Z14: 1 | AB14: 1 | AC14: 1
A15: BL3 | B15: Barrack Yard | D15: Barrack Lane | E15: Blythe | F15: Kathleen | I15: 1 | M15: 1 | Q15: 12 | R15: - | X15: child | Y15: School pupil | AC15: 1
A16: BL3 | B16: Barrack Yard | D16: Barrack Lane | E16: Blythe | F16: Arthur | H16: 1 | N16: 1 | Q16: 17 | S16: 1 | X16: Clerk | Y16: Lace warehouse | Z16: 1 | AB16: 1 | AC16: 1
A17: BL3 | B17: Barrack Yard | D17: Barrack Lane | E17: Bentley | F17: Ernest | H17: 1 | O17: Boarder | Q17: 18 | S17: 1 | X17: Fitter | Y17: Machines | Z17: 1 | AB17: 1 | AC17: 1
A18: BL4 | B18: Barrack Yard | D18: Barrack Lane | E18: Hind | F18: Fletcher | H18: 1 | K18: 1 | Q18: 61 | R18: 1 | X18: Coachman (domestic) | Z18: 1 | AB18: 1 | AC18: 1
A19: BL4 | B19: Barrack Yard | D19: Barrack Lane | E19: Hind | F19: Sarah | G19: 1 | L19: 1 | Q19: 61 | R19: 1 | U19: 34 | V19: 4 | W19: 3 | X19: Lace hand drawer finisher | Z19: 1 | AB19: 1 | AC19: 1
A20: BL4 | B20: Barrack Yard | D20: Barrack Lane | E20: Hind | F20: Edith Annie | G20: 1 | M20: 1 | Q20: 32 | S20: 1 | X20: Machinist (Hosiery) | Z20: 1 | AB20: 1 | AC20: 1
A21: total | C21: 4 | E21: 6 | F21: 18 | G21: =SUM(G3:G20) -> 9 | H21: 7 | I21: 2 | J21: 0 | K21: 4 | L21: 3 | M21: 6 | N21: 2 | O21: 3 | P21: 0 | Q21: 669 | R21: 8 | S21: 7 | T21: 1 | U21: 96 | V21: 12 | W21: 11 | X21: 0 | Y21: 0 | Z21: 12 | AA21: 0 | AB21: 12 | AC21: 15 | AD21: 3
F22: av women | G22: 0.66666667 | P22: average age | Q22: 37.166667 | Z22: av | AA22: 0.66666667 | AC22: 0.83333333
F23: Head | G23: 4 | P23: av age woman | Q23: 33.166667
F24: Wife | G24: 3 | J24: no occupation | K24: =F21-Z21 -> 6
F25: SON | G25: 2
F26: Daughter | G26: 6
F27: Grand daughter | G27: 1
F28: Son in law | G28: 1
F29: Boarder | G29: 1
G30: 18

Sheet PC
A1: House ID | B1: House Name | C1: NO. | D1: Address | E1: Family | F1: Name | G1: W/M/G/B | K1: Relationship to Head of family | Q1: Age | R1: Married/Single/Widow/er | S1: SINGLE | T1: Widow/er | U1: Married yrs | V1: Children born | W1: children living | X1: Personal Occupation | Y1: Industry | Z1: Economic participants | AA1: Employer/worker | AC1: Born | AF1: Note | AG1: Households | AH1: Population | AI1: Family | AJ1: Servants | AK1: Marital status - Married | AL1: Marital status - Single | AM1: Marital Status - Widow/er | AN1: Employer | AO1: Worker | AP1: Place of birth - Nottingham | AQ1: Place of birth - Oher
A2: largest household | B2: smallest household | G2: W | H2: M | I2: G | J2: B | K2: HEAD women head | L2: WIFE | M2: daughter | N2: son | O2: Other | P2: Servant | Q2: If <15=child | R2: Married woman | S2: SINGLE woman | T2: Widow er | AA2: Employer | AB2: worker | AC2: Nottinghamshire | AD2: Other | AG2: 13 | AH2: 62 | AI2: 36 | AJ2: 26 | AK2: 11 | AL2: 37 | AM2: 12 | AN2: 8 | AO2: 28 | AP2: 29 | AQ2: 33
A3: PC1 | C3: 19 | D3: Pelham Crescent | E3: Read | F3: Herbert Wlliam | G3: 0 | H3: 1 | I3: 0 | J3: 0 | K3: 1 | L3: 0 | M3: 0 | N3: 0 | P3: 0 | Q3: 66 | R3: 1 | S3: 0 | T3: 0 | X3: Retired (was coachbuilder) | AA3: 0 | AB3: 0 | AC3: 1
A4: PC1 | C4: 19 | D4: Pelham Crescent | E4: Read | F4: Annie | G4: 1 | H4: 0 | I4: 0 | J4: 0 | K4: 0 | L4: 1 | M4: 0 | N4: 0 | P4: 0 | Q4: 64 | R4: 1 | S4: 0 | T4: 0 | U4: 37 | V4: 4 | W4: 3 | AA4: 0 | AB4: 0 | AC4: 1
A5: PC1 | C5: 19 | D5: Pelham Crescent | E5: Read | F5: Ada Maud | G5: 1 | H5: 0 | I5: 0 | J5: 0 | K5: 0 | L5: 0 | M5: 1 | N5: 0 | P5: 0 | Q5: 34 | R5: 0 | S5: 1 | T5: 0 | X5: No occupation | AA5: 0 | AB5: 0 | AC5: 1
A6: PC1 | C6: 19 | D6: Pelham Crescent | E6: Handon | F6: Maggie | G6: 1 | H6: 0 | I6: 0 | J6: 0 | K6: 0 | L6: 0 | M6: 0 | N6: 0 | P6: 1 | Q6: 18 | R6: 0 | S6: 1 | T6: 0 | X6: Housemaid (domestic servant) | Z6: 1 | AA6: 0 | AB6: 1 | AC6: 1
A7: PC1 | C7: 19 | D7: Pelham Crescent | E7: Shephard | F7: Florece | G7: 1 | H7: 0 | I7: 0 | J7: 0 | K7: 0 | L7: 0 | M7: 0 | N7: 0 | P7: 1 | Q7: 17 | R7: 0 | S7: 1 | T7: 0 | X7: General servant | Z7: 1 | AA7: 0 | AB7: 1 | AD7: 1 | AE7: Wolverhampton
A8: PC2 | C8: 17 | D8: Pelham Crescent | E8: Laing | F8: George Dawson | G8: 0 | H8: 1 | I8: 0 | J8: 0 | K8: 1 | L8: 0 | M8: 0 | N8: 0 | P8: 0 | Q8: 62 | R8: 1 | S8: 0 | T8: 0 | X8: Wine & Spirit Merchant | Z8: 1 | AA8: 1 | AB8: 0 | AD8: 1 | AE8: Birmingham
A9: PC2 | C9: 17 | D9: Pelham Crescent | E9: Laing | F9: Blanche Viola | G9: 1 | H9: 0 | I9: 0 | J9: 0 | K9: 0 | L9: 1 | M9: 0 | N9: 0 | P9: 0 | Q9: 54 | R9: 1 | S9: 0 | T9: 0 | U9: 22 | V9: 1 | W9: 1 | X9: Wine & Spirit Merchant | Z9: 1 | AA9: 1 | AB9: 0 | AD9: 1 | AE9: London
A10: PC2 | C10: 17 | D10: Pelham Crescent | E10: Laing | F10: John Posvenor | G10: 0 | H10: 1 | I10: 0 | J10: 0 | K10: 0 | L10: 0 | M10: 0 | N10: 1 | P10: 0 | Q10: 21 | R10: 0 | S10: 1 | T10: 0 | X10: Wine & Spirit Merchant | Z10: 1 | AA10: 1 | AC10: 1
A11: PC2 | C11: 17 | D11: Pelham Crescent | E11: Laing | F11: John Lysanda | G11: 0 | H11: 1 | I11: 0 | J11: 0 | K11: 0 | L11: 0 | M11: 0 | N11: 0 | O11: brother | P11: 0 | Q11: 56 | R11: 0 | S11: 1 | T11: 0 | X11: wine & Spirit Merchant | Z11: 1 | AA11: 1 | AB11: 0 | AD11: 1 | AE11: Sussex | AF11: Visitor from NZ
A12: PC2 | C12: 17 | D12: Pelham Crescent | E12: Hill | F12: Mary Ann | G12: 1 | H12: 0 | I12: 0 | J12: 0 | K12: 0 | L12: 0 | M12: 0 | N12: 0 | O12: 1 | P12: 0 | Q12: 75 | R12: 0 | S12: 1 | T12: 0 | X12: Retired (was Nurse) | AD12: 1 | AE12: Devon | AF12: Pensioner
A13: PC2 | C13: 17 | D13: Pelham Crescent | E13: Hill | F13: Ruth Mary | G13: 1 | H13: 0 | I13: 0 | J13: 0 | K13: 0 | M13: 0 | N13: 0 | P13: 1 | Q13: 23 | R13: 0 | S13: 1 | T13: 0 | X13: Cook | Z13: 1 | AA13: 0 | AB13: 1 | AC13: 1
A14: PC2 | C14: 17 | D14: Pelham Crescent | E14: Wright | F14: Clara | G14: 1 | H14: 0 | I14: 0 | J14: 0 | K14: 0 | L14: 0 | M14: 0 | N14: 0 | P14: 1 | Q14: 18 | R14: 0 | S14: 1 | T14: 0 | X14: Housemaid | Z14: 1 | AB14: 1 | AD14: 1 | AE14: Lincolnshire
A15: PC2 | C15: 17 | D15: Pelham Crescent | E15: Lander | F15: Sarah Ann | G15: 1 | H15: 0 | I15: 0 | J15: 0 | K15: 0 | L15: 0 | M15: 0 | N15: 0 | P15: 1 | Q15: 16 | R15: 0 | S15: 1 | T15: 0 | X15: Parlourmaid | Z15: 1 | AB15: 1 | AD15: 1 | AE15: Derbyshire
A16: PC3 | C16: 15 | D16: pelham Crescent | E16: Thorpe | F16: Kate | G16: 1 | H16: 0 | I16: 0 | J16: 0 | K16: 1 | L16: 0 | M16: 0 | N16: 0 | P16: 0 | Q16: 75 | R16: 0 | S16: 0 | T16: 1 | U16: 0 | V16: 0 | W16: 0 | X16: Private Means | AD16: 1 | AE16: Belfast
A17: PC3 | C17: 15 | D17: pelham Crescent | E17: Saville | F17: Eliza Helena | G17: 1 | H17: 0 | I17: 0 | J17: 0 | K17: 0 | L17: 0 | M17: 0 | N17: 0 | O17: sister | P17: 0 | Q17: 68 | R17: 0 | S17: 1 | T17: 0 | X17: Private Means | AD17: 1 | AE17: Sussex
A18: PC3 | C18: 15 | D18: pelham Crescent | E18: Parkin | F18: Maud | G18: 1 | H18: 0 | I18: 0 | J18: 0 | K18: 0 | L18: 0 | M18: 0 | N18: 0 | P18: 1 | Q18: 26 | S18: 1 | T18: 0 | X18: Domestic | Z18: 1 | AB18: 1 | AD18: 1 | AE18: Derbyshire
A19: PC3 | C19: 15 | D19: pelham Crescent | E19: Winsor | F19: Elizabeth | G19: 1 | H19: 0 | I19: 0 | J19: 0 | K19: 0 | L19: 0 | M19: 0 | N19: 0 | P19: 1 | Q19: 52 | R19: 0 | S19: 0 | T19: 1 | X19: Temporary Help | Z19: 1 | AB19: 1 | AD19: 1 | AE19: Northants
A20: PC4 | C20: 13 | D20: Pelham Crescent | E20: Flersheim | F20: Gustav Albert | G20: 0 | H20: 1 | I20: 0 | J20: 0 | K20: 1 | L20: 0 | M20: 0 | N20: 0 | O20: 0 | P20: 0 | Q20: 56 | R20: 1 | X20: Director | Y20: lace curtain manuf | Z20: 1 | AA20: 1 | AD20: 1 | AE20: Germany
A21: PC4 | C21: 13 | D21: Pelham Crescent | E21: Flersheim | F21: Caroline Hannah | G21: 1 | H21: 0 | I21: 0 | J21: 0 | K21: 0 | L21: 1 | M21: 0 | N21: 0 | P21: 0 | Q21: 52 | R21: 1 | S21: 0 | T21: 0 | U21: 12 | V21: 1 | W21: 1 | AC21: 1
A22: PC4 | C22: 13 | D22: Pelham Crescent | E22: Flersheim | F22: Katherine Mary Monica | I22: 1 | M22: 1 | P22: 0 | Q22: 12 | X22: child | AC22: 1
A23: PC4 | C23: 13 | D23: Pelham Crescent | E23: Wildbore | F23: Sarah Ann | G23: 1 | P23: 1 | Q23: 34 | S23: 1 | X23: cook | Z23: 1 | AB23: 1 | AC23: 1
A24: PC4 | C24: 13 | D24: Pelham Crescent | E24: Mathews | F24: Amy | G24: 1 | P24: 1 | Q24: 21 | S24: 1 | X24: housemaid | Z24: 1 | AB24: 1 | AD24: 1 | AE24: Derbyshire
A25: PC4 | C25: 13 | D25: Pelham Crescent | E25: Halatschek | F25: Maria | G25: 1 | P25: 1 | Q25: 24 | S25: 1 | X25: Governess | Z25: 1 | AB25: 1 | AD25: 1 | AE25: Germany
A26: PC5 | C26: 11 | D26: Pelham Crescent | E26: Kohn | F26: Recha | G26: 1 | H26: 0 | I26: 0 | J26: 0 | K26: 1 | L26: 0 | M26: 0 | N26: 0 | P26: 0 | Q26: 77 | R26: 0 | S26: 0 | T26: 1 | U26: 57 | V26: 8 | W26: 8 | AD26: 1 | AE26: Germany
A27: PC5 | C27: 11 | D27: Pelham Crescent | E27: Kohn | F27: Amy | G27: 1 | M27: 1 | Q27: 38 | S27: 1 | U27: 38 | AC27: 1
A28: PC5 | C28: 11 | D28: Pelham Crescent | E28: Whistler | F28: Alice | G28: 1 | P28: 1 | Q28: 22 | S28: 1 | X28: housemaid | Z28: 1 | AB28: 1 | AC28: 1
A29: PC5 | C29: 11 | D29: Pelham Crescent | E29: Hutchinson | F29: Hannah | G29: 1 | P29: 1 | Q29: 35 | R29: 1 | U29: 7 | V29: 2 | W29: 2 | X29: cook | Z29: 1 | AB29: 1 | AD29: 1 | AE29: worceshire
A30: PC6 | C30: 9 | D30: Pelham Crescent | E30: Adams | F30: Catherine Lucy | G30: 1 | H30: 0 | I30: 0 | J30: 0 | K30: 1 | L30: 0 | M30: 0 | N30: 0 | P30: 0 | Q30: 79 | R30: 0 | S30: 1 | T30: 0 | U30: 0 | V30: 0 | W30: 0 | X30: Private Means | AC30: 1 | AF30: note that women who employed servants are not counted as employers
A31: PC6 | C31: 9 | D31: Pelham Crescent | E31: Martin | F31: Emma Elizabeth | G31: 1 | P31: 1 | Q31: 44 | S31: 1 | X31: Cook | Z31: 1 | AB31: 1 | AD31: 1 | AE31: Derbyshire
A32: PC6 | C32: 9 | D32: Pelham Crescent | E32: Else | F32: Francis Gertrude | G32: 1 | P32: 1 | Q32: 26 | S32: 1 | X32: Parlourmaid | Z32: 1 | AB32: 1 | AD32: 1 | AE32: Lincolnshire
A33: PC6 | C33: 9 | D33: Pelham Crescent | E33: Stope | F33: Sarah Annie | G33: 1 | P33: 1 | Q33: 26 | S33: 1 | X33: Housemaid | Z33: 1 | AB33: 1 | AD33: 1 | AE33: Derbyshire
A34: PC7 | C34: No entry | D34: No entry | E34: No entry | F34: No entry | G34: No entry | H34: No entry | I34: No entry | J34: No entry | K34: No entry | L34: No entry | M34: No entry | N34: No entry | P34: No entry | Q34: No entry | R34: No entry | S34: No entry | T34: No entry | U34: No entry | V34: No entry | W34: No entry | X34: No entry | Y34: No entry | AA34: No entry | AB34: No entry | AC34: No entry | AD34: No entry | AE34: No entry
A35: PC8 | C35: 5 | D35: Pelham Crescent | E35: Flersheim | F35: Kathinka Elizabeth | G35: 1 | H35: 0 | I35: 0 | J35: 0 | K35: 1 | L35: 0 | M35: 0 | N35: 0 | P35: 0 | Q35: 79 | R35: 0 | S35: 0 | T35: 1 | U35: 0 | V35: 4 | W35: 2 | AD35: 1 | AE35: Germany
A36: PC8 | C36: 5 | D36: Pelham Crescent | E36: North | F36: Annie | G36: 1 | P36: 1 | Q36: 53 | S36: 1 | X36: Cook | Z36: 1 | AB36: 1 | AC36: 1
A37: PC8 | C37: 5 | D37: Pelham Crescent | E37: Slater | F37: Annie | G37: 1 | P37: 1 | Q37: 25 | S37: 1 | X37: Housemaid | Z37: 1 | AB37: 1 | AD37: 1 | AE37: Derbyshire
A38: PC9 | C38: 3 | D38: Pelham Crescent | E38: Lewis | F38: Anna Rebekah | G38: 1 | H38: 0 | I38: 0 | J38: 0 | K38: 1 | L38: 0 | M38: 0 | N38: 0 | P38: 0 | Q38: 70 | R38: 0 | S38: 0 | T38: 1 | U38: 0 | V38: 2 | W38: 2 | AD38: 1 | AE38: Leicestershire
A39: PC9 | C39: 3 | D39: Pelham Crescent | E39: Lewis | F39: Fanny G | G39: 1 | M39: 1 | Q39: 42 | S39: 1 | AC39: 1
A40: PC9 | C40: 3 | D40: Pelham Crescent | E40: Lewis | F40: Arthur B | H40: 1 | N40: 1 | Q40: 40 | T40: 1 | X40: Hosiery manuf | Z40: 1 | AA40: 1 | AC40: 1
...

Sheet WesternTerrace
A1: House ID | B1: House Name | C1: NO. | D1: Address | E1: Family | F1: Name | G1: W/M/G/B | K1: Relationship to Head of family | Q1: Age | R1: Married/Single/Widow/er | S1: SINGLE | T1: Widow/er | U1: Married yrs | V1: Children born | W1: children living | X1: Personal Occupation | Y1: Industry | Z1: Economic participants | AA1: Employer/worker | AC1: Born | AE1: Note
A2: largest household | B2: smallest household | G2: W | H2: M | I2: G | J2: B | K2: HEAD women head | L2: WIFE | M2: daughter | N2: son | O2: Other | P2: Servant | Q2: If <15=child | R2: Married woman | S2: SINGLE woman | T2: Widow er | AA2: Employer | AB2: worker | AC2: Nottinghamshire | AD2: Other
A3: WT1 | C3: 8 | D3: Western Terrace | E3: Bradley | F3: Frederick James | H3: 1 | K3: 1 | Q3: 65 | R3: 1 | X3: Director of Lt Leicester works | Z3: 1 | AA3: 1 | AC3: 1
A4: WT1 | C4: 8 | D4: Western Terrace | E4: Bradley | F4: Emily Margaret | G4: 1 | L4: 1 | Q4: 63 | R4: 1 | U4: 40 | V4: 4 | W4: 3 | AD4: Glam
A5: WT1 | C5: 8 | D5: Western Terrace | E5: Bradley | F5: Gladys Margaret | G5: 1 | M5: 1 | Q5: 30 | S5: 1 | X5: Teacher of children | Z5: 1 | AB5: 1 | AC5: 1
A6: WT1 | C6: 8 | D6: Western Terrace | E6: James | F6: Martha | G6: 1 | P6: 1 | Q6: 69 | S6: 1 | X6: Cook | Z6: 1 | AB6: 1 | AD6: Glous
A7: WT1 | C7: 8 | D7: Western Terrace | E7: Diss | F7: Sarah Jane | G7: 1 | P7: 1 | Q7: 17 | S7: 1 | X7: Housemaid | Z7: 1 | AB7: 1 | AD7: Lincolnshire
A8: WT1 | C8: 8 | D8: Western Terrace | E8: Borbrid | F8: Mabel Alice | G8: 1 | P8: 1 | Q8: 22 | S8: 1 | X8: Housemaid | Z8: 1 | AB8: 1 | AD8: Yorkshire
A9: WT2 | C9: 9 | D9: Western Terrace | E9: Clarke | F9: Alfred Harriman | H9: 1 | K9: 1 | Q9: 61 | R9: 1 | X9: Lace Manuf | Z9: 1 | AA9: 1 | AC9: 1
A10: WT2 | C10: 9 | D10: Western Terrace | E10: Clarke | F10: Annie Maria | G10: 1 | L10: 1 | Q10: 56 | R10: 1 | U10: 31 | V10: 2 | W10: 2 | AC10: 1
A11: WT2 | C11: 9 | D11: Western Terrace | E11: Clarke | F11: Alfred Cecil | H11: 1 | N11: 1 | Q11: 29 | S11: 1 | X11: assisting in the business | Z11: 1 | AB11: 1 | AC11: 1
A12: WT2 | C12: 9 | D12: Western Terrace | E12: Clarke | F12: Gerald | H12: 1 | N12: 1 | Q12: 28 | S12: 1 | X12: assisting in the business | Z12: 1 | AB12: 1 | AC12: 1
A13: WT2 | C13: 9 | D13: Western Terrace | E13: Hebb | F13: Gertrude Annie | G13: 1 | P13: 1 | Q13: 26 | S13: 1 | X13: domestic | Z13: 1 | AB13: 1 | AC13: 1
A14: WT2 | C14: 9 | D14: Western Terrace | E14: Hatherley | F14: Mary | G14: 1 | P14: 1 | Q14: 24 | S14: 1 | X14: domestic | Z14: 1 | AB14: 1 | AD14: lincolnshire
A15: WT2 | C15: 9 | D15: Western Terrace | E15: Wilson | F15: Edith | G15: 1 | P15: 1 | Q15: 27 | S15: 1 | X15: domestic | Z15: 1 | AB15: 1 | AC15: 1
A16: WT3 | C16: 10 | D16: Western Terrace | E16: Clarke | F16: Charles Henry | H16: 1 | K16: 1 | Q16: 62 | S16: 1 | X16: Lace Manuf | Z16: 1 | AA16: 1 | AC16: 1
A17: WT3 | C17: 10 | D17: Western Terrace | E17: Clarke | F17: Ellen Maria | G17: 1 | O17: sister | Q17: 56 | S17: 1 | X17: Private Means | AC17: 1
A18: WT3 | C18: 10 | D18: Western Terrace | E18: Bartle | F18: Louie | G18: 1 | P18: 1 | Q18: 22 | S18: 1 | X18: Cook | Z18: 1 | AB18: 1 | AD18: lincolnshire
A19: WT3 | C19: 10 | D19: Western Terrace | E19: Phillips | F19: Elizabeth Mary | G19: 1 | P19: 1 | Q19: 25 | S19: 1 | X19: Housemaid | Z19: 1 | AB19: 1 | AC19: 1
A20: WT4 | B20: Lincoln Villa | D20: Western Terrace | E20: Bright | F20: Joseph | H20: 1 | K20: 1 | Q20: 61 | T20: 1 | X20: Solicitor | Z20: 1 | AA20: 1 | AC20: 1 | AE20: Signed Sir J Bright
A21: WT4 | B21: Lincoln Villa | D21: Western Terrace | E21: Bright | F21: Horace Dickinson | H21: 1 | N21: 1 | Q21: 29 | S21: 1 | X21: Solicitor | Z21: 1 | AA21: 1 | AC21: 1
A22: WT4 | B22: Lincoln Villa | D22: Western Terrace | E22: Bright | F22: Josephine Agnes | G22: 1 | M22: 1 | Q22: 28 | S22: 1 | AC22: 1
A23: WT4 | B23: Lincoln Villa | D23: Western Terrace | E23: Bright | F23: Beatrice Eveline | G23: 1 | M23: 1 | Q23: 29 | S23: 1 | AC23: 1
A24: WT4 | B24: Lincoln Villa | D24: Western Terrace | E24: Bright | F24: Alfred Stanley | H24: 1 | N24: 1 | Q24: 25 | S24: 1 | X24: Solicitor | Z24: 1 | AA24: 1 | AC24: 1
A25: WT4 | B25: Lincoln Villa | D25: Western Terrace | E25: Bright | F25: Frank Arnold | H25: 1 | N25: 1 | Q25: 24 | S25: 1 | X25: Mechanical Engineer | Y25: Tobacco factory | Z25: 1 | AB25: 1 | AC25: 1
A26: WT4 | B26: Lincoln Villa | D26: Western Terrace | E26: Davis | F26: Edith | G26: 1 | P26: 1 | Q26: 42 | S26: 1 | X26: Sick Nurse (own means) | Z26: 1 | AB26: 1 | AD26: Middx
A27: WT4 | B27: Lincoln Villa | D27: Western Terrace | E27: Wareham | F27: Elizabeth | G27: 1 | P27: 1 | Q27: 45 | S27: 1 | X27: Cook | Z27: 1 | AB27: 1 | AD27: ?
A28: WT4 | B28: Lincoln Villa | D28: Western Terrace | E28: Porteous | F28: Alice | G28: 1 | P28: 1 | Q28: 31 | S28: 1 | X28: Parlourmaid | Z28: 1 | AB28: 1 | AC28: 1
A29: WT4 | B29: Lincoln Villa | D29: Western Terrace | E29: Frost | F29: Edith | G29: 1 | P29: 1 | Q29: 20 | S29: 1 | X29: Housemaid | Z29: 1 | AB29: 1 | AC29: 1
A30: WT4 | B30: Lincoln Villa | D30: Western Terrace | E30: Inskip | F30: Annie | G30: 1 | P30: 1 | Q30: 16 | S30: 1 | X30: Kitchenmaid | Z30: 1 | AB30: 1 | AD30: Somercotes
A31: TOTAL | B31: 4 | E31: 17 | F31: 28 | G31: =SUM(G3:G30) -> 19 | H31: =SUM(H3:H30) -> 9 | I31: =SUM(I3:I30) -> 0 | J31: =SUM(J3:J30) -> 0 | K31: =SUM(K3:K30) -> 4 | L31: =SUM(L3:L30) -> 2 | M31: =SUM(M3:M30) -> 3 | N31: =SUM(N3:N30) -> 5 | O31: 1 | P31: =SUM(P3:P30) -> 13 | Q31: =SUM(Q3:Q30) -> 1032 | R31: =SUM(R3:R30) -> 4 | S31: =SUM(S3:S30) -> 23 | T31: =SUM(T3:T30) -> 1 | U31: =SUM(U3:U30) -> 71 | V31: =SUM(V3:V30) -> 6 | W31: =SUM(W3:W30) -> 5 | Z31: =AB31+AA31 -> 23 | AA31: =SUM(AA3:AA30) -> 6 | AB31: =SUM(AB3:AB30) -> 17 | AC31: =SUM(AC3:AC30) -> 19 | AD31: =F31-AC31 -> 9
A33: Households | B33: Population | C33: Family | D33: Servants | E33: Marital status - Married | F33: Marital status - Single | G33: Marital Status - Widow/er | H33: Employer | I33: Worker | J33: Place of birth - Nottingham | K33: Place of birth - Oher
A34: 4 | B34: 28 | C34: 17 | D34: 13 | E34: 4 | F34: 23 | G34: 1 | H34: 6 | I34: 17 | J34: 19 | K34: =B34-J34 -> 9

Sheet North Rd
A1: House ID | B1: House Name | C1: NO. | D1: Address | E1: Family | F1: Name | G1: W/M/G/B | K1: Relationship to Head of family | Q1: Age | R1: Married/Single/Widow/er | S1: SINGLE | T1: Widow/er | U1: Married yrs | V1: Children born | W1: children living | X1: Personal Occupation | Y1: Industry | Z1: Economic participants | AA1: Employer/worker | AC1: Born | AE1: Note | AF1: Street/Occupation | AG1: Park Keeper | AH1: Manager | AI1: Valuer | AJ1: Accountant | AK1: Blousehand | AL1: Cabinet maker | AM1: Clergy | AN1: Clerk | AO1: Coachman | AP1: Director | AQ1: Domestic help (other than servant) | AR1: Fitter | AS1: Gardener | AT1: Lacehand drawer finisher | AU1: Machinist | AV1: Manufacturer | AW1: Merchant | AX1: Private Means | AY1: Retired | AZ1: Tailoress (Seamstress) | BA1: Typist | BB1: Warper
A2: largest household | B2: smallest household | G2: W | H2: M | I2: G | J2: B | K2: HEAD women head | L2: WIFE | M2: daughter | N2: son | O2: Other | P2: Servant | Q2: If <15=child | R2: Married woman | S2: SINGLE woman | T2: Widow er | AA2: Employer | AB2: worker | AC2: Nottinghamshire | AD2: Other | AG2: 1 | AH2: 1 | AI2: 1
A3: NR1 | B3: Gate House | D3: North Rd | E3: Hallam | F3: Thomas | H3: 1 | K3: 1 | Q3: 66 | R3: 1 | X3: Park Keeper | AA3: 1 | AC3: 1
A4: NR1 | B4: Gate House | D4: North Rd | E4: Hallam | F4: Emily | G4: 1 | L4: 1 | Q4: 40 | R4: 1 | U4: 4 | AD4: Cheshire
A5: NR2 | B5: North Lodge | D5: North Rd | E5: Huskinson | F5: Percy | H5: 1 | K5: 1 | Q5: 38 | R5: 1 | X5: Manager | Y5: moston factory | AA5: 1 | AC5: 1
A6: NR2 | B6: North Lodge | D6: North Rd | E6: Huskinson | F6: Muriel | G6: 1 | L6: 1 | Q6: 30 | R6: 1 | U6: 11 | V6: 2 | W6: 2 | AC6: 1
A7: NR2 | B7: North Lodge | D7: North Rd | E7: Huskinson | F7: Geoffrey | H7: 1 | N7: 1 | Q7: 16 | AC7: 1
A8: NR2 | B8: North Lodge | D8: North Rd | E8: Huskinson | F8: Leonard | H8: 1 | N8: 1 | Q8: 5 | AC8: 1
A9: NR2 | B9: North Lodge | D9: North Rd | E9: Huskinson | F9: Ernest | H9: 1 | O9: Brother | Q9: 35 | S9: 1 | X9: valuer | Y9: inland revenue | AB9: 1 | AC9: 1
A10: NR2 | B10: North Lodge | D10: North Rd | E10: Smith | F10: Bertha | G10: 1 | P10: 1 | Q10: 20 | S10: 1 | X10: housemaid | AB10: 1 | AD10: derbyshire
A11: NR2 | B11: North Lodge | D11: North Rd | E11: Ormston | F11: Francis | G11: 1 | P11: 1 | Q11: 38 | S11: 1 | X11: cook | AB11: 1 | AD11: Leicestershire
A12: NR2 | B12: North Lodge | D12: North Rd | E12: Yareham | F12: Anne | G12: 1 | P12: 1 | Q12: 24 | S12: 1 | X12: parlourmaid | AB12: 1 | AC12: 1
A13: TOTAL | B13: 2 | E13: 5 | F13: 10 | G13: =SUM(G3:G12) -> 5 | H13: =SUM(H3:H12) -> 5 | I13: =SUM(I3:I12) -> 0 | J13: =SUM(J3:J12) -> 0 | K13: =SUM(K3:K12) -> 2 | L13: =SUM(L3:L12) -> 2 | M13: =SUM(M3:M12) -> 0 | N13: =SUM(N3:N12) -> 2 | O13: 1 | P13: =SUM(P3:P12) -> 3 | Q13: =SUM(Q3:Q12) -> 312 | R13: =SUM(R3:R12) -> 4 | S13: =SUM(S3:S12) -> 4 | T13: =SUM(T3:T12) -> 0 | U13: =SUM(U3:U12) -> 15 | V13: =SUM(V3:V12) -> 2 | W13: =SUM(W3:W12) -> 2 | ... Y13: =SUM(Y3:Y12) -> 0 | Z13: =AA13+AB13 -> 6 | AA13: =SUM(AA3:AA12) -> 2 | AB13: =SUM(AB3:AB12) -> 4 | AC13: =SUM(AC3:AC12) -> 7 | AD13: 3
G14: =G13+H13+I13+J13 -> 10 | K14: =K13+L13+M13+N13+O13+P13 -> 10 | Q14: =Q13/K14 -> 31.2

Sheet Lincoln Circus
A1: House ID | B1: House Name | C1: NO. | D1: Address | E1: Family | F1: Name | G1: W/M/G/B | K1: Relationship to Head of family | Q1: Age | R1: Married/Single/Widow/er | S1: SINGLE | T1: Widow/er | U1: Married yrs | V1: Children born | W1: children living | X1: Personal Occupation | Y1: Industry | Z1: Economic participants | AA1: Employer/worker | AC1: Born | AE1: Note
A2: largest household | B2: smallest household | G2: W | H2: M | I2: G | J2: B | K2: HEAD women head | L2: WIFE | M2: daughter | N2: son | O2: Other | P2: Servant | Q2: If <15=child | R2: Married woman | S2: SINGLE woman | T2: Widow er | AA2: Employer | AB2: worker | AC2: Nottinghamshire | AD2: Other
A3: LC1 | D3: Lincoln Circus | E3: Tune | F3: Annie Elizabeth | G3: 1 | P3: 1 | Q3: 47 | S3: 1 | X3: Cook | Z3: 1 | AB3: 1 | AD3: Lincs
A4: LC1 | D4: Lincoln Circus | E4: Wright | F4: Alice Ada | G4: 1 | P4: 1 | Q4: 35 | S4: 1 | X4: Parlourmaid | Z4: 1 | AB4: 1 | AD4: Herts
A5: LC1 | D5: Lincoln Circus | E5: Swaly | F5: Florence | G5: 1 | P5: 1 | Q5: 24 | S5: 1 | X5: Housemaid | Z5: 1 | AB5: 1 | AC5: 1
A6: LC2 | B6: The Cottage | D6: Lincoln Circus | E6: Palmer | F6: Edward | H6: 1 | K6: 1 | Q6: 48 | R6: 1 | X6: Gardener | Y6: Domestic | Z6: 1 | AB6: 1 | AD6: Clackmannanshire
A7: LC2 | B7: The Cottage | D7: Lincoln Circus | E7: Palmer | F7: Alice | G7: 1 | L7: 1 | Q7: 52 | R7: 1 | U7: 25 | V7: 5 | W7: 5 | AD7: Derbyshire
A8: LC2 | B8: The Cottage | D8: Lincoln Circus | E8: Palmer | F8: William Edward | H8: 1 | N8: 1 | Q8: 23 | S8: 1 | X8: Telephone Mechanic | Y8: Nat Telephone | Z8: 1 | AB8: 1 | AC8: 1
A9: LC2 | B9: The Cottage | D9: Lincoln Circus | E9: Palmer | F9: Charles Harry | H9: 1 | N9: 1 | Q9: 21 | S9: 1 | X9: Bookeeper | Y9: Printing | Z9: 1 | AB9: 1 | AC9: 1
A10: LC2 | B10: The Cottage | D10: Lincoln Circus | E10: Palmer | F10: Alfred Ernest | H10: 1 | N10: 1 | Q10: 19 | S10: 1 | X10: Clerk | Y10: Nat Telephone | Z10: 1 | AB10: 1 | AC10: 1
A11: LC2 | B11: The Cottage | D11: Lincoln Circus | E11: Palmer | F11: George Albert | H11: 1 | N11: 1 | Q11: 17 | S11: 1 | X11: Warehouse Apprentice | Y11: Lace | Z11: 1 | AB11: 1 | AC11: 1
A12: LC2 | B12: The Cottage | D12: Lincoln Circus | E12: Palmer | F12: Mary Helena | G12: 1 | M12: 1 | Q12: 15 | S12: 1 | X12: Student Governess | Y12: School | Z12: 1 | AB12: 1 | AC12: 1
A13: TOTAL | B13: 2 | E13: 4 | F13: 10 | G13: =SUM(G3:G12) -> 5 | H13: =SUM(H3:H12) -> 5 | I13: =SUM(I3:I12) -> 0 | J13: =SUM(J3:J12) -> 0 | K13: =SUM(K3:K12) -> 1 | L13: =SUM(L3:L12) -> 1 | M13: =SUM(M3:M12) -> 1 | N13: =SUM(N3:N12) -> 4 | ... AC13: =SUM(AC3:AC12) -> 6 | AD13: 4

Sheet newcastlecircus
A1: House ID | B1: House Name | C1: NO. | D1: Address | E1: Family | F1: Name | G1: W/M/G/B | K1: Relationship to Head of family | Q1: Age | R1: Married/Single/Widow/er | S1: SINGLE | T1: Widow/er | U1: Married yrs | V1: Children born | W1: children living | X1: Personal Occupation | Y1: Industry | Z1: Economic participants | AA1: Employer/worker | AC1: Born | AE1: Note
A2: largest household | B2: smallest household | G2: W | H2: M | I2: G | J2: B | K2: HEAD women head | L2: WIFE | M2: daughter | N2: son | O2: Other | P2: Servant | Q2: If <15=child | R2: Married woman | S2: SINGLE woman | T2: Widow er | AA2: Employer | AB2: worker | AC2: Nottinghamshire | AD2: Other
A3: NC1 | B3: Elm | E3: Birkin | F3: Charles Milfred | H3: 1 | K3: 1 | Q3: 45 | R3: 1 | X3: Lace Manuf | Z3: 1 | AA3: 1 | AC3: 1
A4: NC1 | B4: Elm | E4: Birkin | F4: Sarah Ann | G4: 1 | P4: 1 | Q4: 41 | S4: 1 | X4: Cook | AB4: 1 | AC4: 1 | AE4: member of family is cook
A5: NC1 | B5: Elm | E5: Ellis | F5: Elizabeth | G5: 1 | P5: 1 | Q5: 28 | S5: 1 | X5: Housemaid | AB5: 1 | AD5: Staffs
A6: NC1 | B6: Elm | E6: Castledine | F6: Gertrude Jessee | G6: 1 | P6: 1 | Q6: 22 | S6: 1 | X6: Parlour maid | AB6: 1 | AD6: Staffs
A7: NC1 | B7: Elm | E7: Cyre | F7: Julia Hannah | G7: 1 | P7: 1 | Q7: 20 | S7: 1 | X7: housemaid | AB7: 1 | AD7: Derby
A8: NC1 | B8: Elm | E8: Walker | F8: Kentler | G8: 1 | P8: 1 | Q8: 20 | S8: 1 | X8: kitchenmaid | AB8: 1 | AD8: Derby
A9: NC1 | B9: Elm | E9: Riley | F9: Rupert | H9: 1 | O9: visitor | Q9: 36 | R9: 1 | X9: Army capt | AB9: 1 | AD9: USA
A10: NC2 | B10: Burton | E10: Hutchinson | F10: Sarah | G10: 1 | Q10: 49 | S10: 1 | X10: Ladies Comp | AB10: 1 | AC10: 1
A11: NC2 | B11: Burton | E11: Clarke | F11: Emma | G11: 1 | K11: 1 | P11: 1 | Q11: 60 | S11: 1 | X11: Domestic servant | AB11: 1 | AD11: leics
A12: NC2 | B12: Burton | E12: Ward | F12: Mary Ann | G12: 1 | P12: 1 | Q12: 51 | S12: 1 | X12: Domestic servant | AB12: 1 | AC12: 1
A13: NC2 | B13: Burton | E13: Burnett | F13: Mary | G13: 1 | P13: 1 | Q13: 42 | S13: 1 | X13: Domestic servant | AB13: 1 | AD13: lincs
A14: NC2 | B14: Burton | E14: Ruff | F14: Louisa | G14: 1 | P14: 1 | Q14: 16 | S14: 1 | X14: Domestic servant | AB14: 1 | AC14: 1
A15: NC2 | B15: Burton | E15: Hemsley | F15: Stanley | H15: 1 | P15: 1 | Q15: 16 | S15: 1 | X15: Domestic servant | AB15: 1 | AC15: 1
A16: NC2 | B16: Burton | E16: Watson | F16: Elizabeth A | G16: 1 | Q16: 75 | T16: 1 | X16: Private means | AC16: 1 | AE16: born The Park
A17: NC3 | B17: Castlethorpe | E17: Lancashire | F17: Francis | H17: 1 | K17: 1 | Q17: 41 | S17: 1 | X17: hosiery manuf | AA17: 1 | AC17: 1
A18: NC3 | B18: Castlethorpe | E18: Taylor | F18: Helen | G18: 1 | O18: sister | Q18: 40 | T18: 1 | U18: 2 | V18: 1 | W18: 1 | AC18: 1
A19: NC3 | B19: Castlethorpe | E19: Taylor | F19: Edith Joan | G19: 1 | O19: niece | Q19: 12 | AD19: lincs
A20: NC3 | B20: Castlethorpe | E20: Recordon | F20: Nellie Lucie | G20: 1 | P20: 1 | Q20: 23 | X20: governess | AB20: 1 | AD20: Switzerland
A21: NC3 | B21: Castlethorpe | E21: Janes | F21: Sabina | G21: 1 | P21: 1 | Q21: 43 | X21: cook | AB21: 1 | AD21: Bucks
A22: NC3 | B22: Castlethorpe | E22: Curtis | F22: Lily | G22: 1 | P22: 1 | Q22: 24 | X22: housemaid | AB22: 1 | AC22: 1
A23: NC4 | E23: Goddard | F23: H Ernest | H23: 1 | K23: 1 | Q23: 42 | R23: 1 | X23: Dental surgeon | AA23: 1 | AC23: 1
A24: NC4 | E24: Goddard | F24: Alice | G24: 1 | L24: 1 | Q24: 46 | R24: 1 | U24: 13 | AC24: 1
A25: NC4 | E25: Jacklin | F25: Mildred | G25: 1 | P25: 1 | Q25: 46 | S25: 1 | X25: Domestic Serv | AB25: 1 | AD25: Lincs
A26: NC4 | E26: Bennett | F26: Annie | G26: 1 | P26: 1 | Q26: 26 | S26: 1 | X26: Parlour maid | AB26: 1 | AD26: Lincs
A27: NC4 | E27: Sharman | F27: Rosa Ella | G27: 1 | P27: 1 | Q27: 17 | S27: 1 | X27: Housemaid | AB27: 1 | AD27: Northants
A28: TOTAL | B28: 4 | E28: 22 | F28: =SUM(G28:J28) -> 25 | G28: =SUM(G3:G27) -> 20 | H28: =SUM(H3:H27) -> 5 | I28: =SUM(I3:I27) -> 0 | J28: =SUM(J3:J27) -> 0 | K28: =SUM(K3:K27) -> 4 | L28: =SUM(L3:L27) -> 1 | M28: =SUM(M3:M27) -> 0 | N28: =SUM(N3:N27) -> 0 | O28: 3 | P28: =SUM(P3:P27) -> 16 | Q28: =SUM(Q3:Q27) -> 881 | R28: =SUM(R3:R27) -> 4 | S28: =SUM(S3:S27) -> 15 | T28: =SUM(T3:T27) -> 2 | U28: =SUM(U3:U27) -> 15 | V28: =SUM(V3:V27) -> 1 | W28: =SUM(W3:W27) -> 1 | ... Y28: =SUM(Y3:Y27) -> 0 | Z28: =AA28+AB28 -> 21 | AA28: =SUM(AA3:AA27) -> 3 | AB28: =SUM(AB3:AB27) -> 18 | AC28: =SUM(AC3:AC27) -> 12 | AD28: =F28-AC28 -> 13

Sheet Park Drive
A1: House ID | B1: House Name | C1: NO. | D1: Address | E1: Family | F1: Name | G1: W/M/G/B | K1: Relationship to Head of family | Q1: Age | R1: Married/Single/Widow/er | S1: SINGLE | T1: Widow/er | U1: Married yrs | V1: Children born | W1: children living | X1: Personal Occupation | Y1: Industry | Z1: Economic participants | AA1: Employer/worker | AC1: Born | AE1: Note
A2: largest household | B2: smallest household | G2: W | H2: M | I2: G | J2: B | K2: HEAD women head | L2: WIFE | M2: daughter | N2: son | O2: Other | P2: Servant | Q2: If <15=child | R2: Married woman | S2: SINGLE woman | T2: Widow er | AA2: Employer | AB2: worker | AC2: Nottinghamshire | AD2: Other shire
A3: PD1 | D3: Park Drive | E3: Homberger | F3: Otto | H3: 1 | K3: 1 | Q3: 59 | R3: 1 | X3: Merchant | Z3: 1 | AA3: 1 | AD3: Germany
A4: PD1 | D4: Park Drive | E4: Homberger | F4: Kate A | G4: 1 | L4: 1 | Q4: 46 | R4: 1 | U4: 24 | AC4: 1
A5: PD1 | D5: Park Drive | E5: Ganderton | F5: Nellie | G5: 1 | P5: 1 | Q5: 16 | S5: 1 | X5: Cook | Z5: 1 | AB5: 1 | AD5: London
A6: PD1 | D6: Park Drive | E6: Pittaway | F6: Emma | G6: 1 | P6: 1 | Q6: 24 | S6: 1 | X6: Parlourmaid | Z6: 1 | AB6: 1 | AD6: Cheshire
A7: PD1 | D7: Park Drive | E7: Jones | F7: Alice | G7: 1 | P7: 1 | Q7: 24 | S7: 1 | X7: Housemaid | Z7: 1 | AB7: 1 | AD7: Bucks
A8: PD1 | D8: Park Drive | E8: Pulford | F8: Edna | G8: 1 | P8: 1 | Q8: 17 | S8: 1 | X8: Kitchenmaid | Z8: 1 | AB8: 1 | AC8: 1
A9: PD2 | B9: Clumber | D9: Park Drive | E9: Gregory | F9: William Godfrey | H9: 1 | K9: 1 | Q9: 77 | T9: 1 | X9: Plain & Spot Net Manuf | Z9: 1 | AA9: 1 | AC9: 1
A10: PD2 | B10: Clumber | D10: Park Drive | E10: Gregory | F10: Charles Arthur | H10: 1 | N10: 1 | Q10: 45 | S10: 1 | AC10: 1
A11: PD2 | B11: Clumber | D11: Park Drive | E11: Gregory | F11: Ellen Augusta | G11: 1 | M11: 1 | Q11: 47 | S11: 1 | AC11: 1
A12: PD2 | B12: Clumber | D12: Park Drive | E12: Marler | F12: Gladys Eslie | G12: 1 | P12: 1 | Q12: 20 | S12: 1 | X12: General serv | Z12: 1 | AB12: 1 | AC12: 1
A13: PD2 | B13: Clumber | D13: Park Drive | E13: Wildmore | F13: Maud Mary | G13: 1 | P13: 1 | Q13: 32 | S13: 1 | X13: General serv | Z13: 1 | AB13: 1 | AD13: Lincs
A14: PD2 | B14: Clumber | D14: Park Drive | E14: Wilkinson | F14: Sarah Elizabeth | G14: 1 | P14: 1 | Q14: 28 | S14: 1 | X14: General serv | Z14: 1 | AB14: 1 | AD14: Lincs
A15: PD3 | C15: 3 | D15: Park Drive | E15: Mellers | F15: Henry James | H15: 1 | K15: 1 | Q15: 59 | R15: 1 | X15: Lace manuf | Z15: 1 | AA15: 1 | AC15: 1
A16: PD3 | C16: 3 | D16: Park Drive | E16: Mellers | F16: Phebe | G16: 1 | L16: 1 | Q16: 57 | R16: 1 | U16: 36 | V16: 4 | W16: 3 | AD16: derby
A17: PD3 | C17: 3 | D17: Park Drive | E17: Mellers | F17: Phebe Agnes Marjorie | I17: 1 | M17: 1 | Q17: 15 | S17: 1 | X17: scholar | AC17: 1 | AE17: the park
A18: PD3 | C18: 3 | D18: Park Drive | E18: Knott | F18: Daisy | G18: 1 | P18: 1 | Q18: 23 | S18: 1 | X18: cook | Z18: 1 | AB18: 1 | AD18: leics
A19: PD3 | C19: 3 | D19: Park Drive | E19: Cluer | F19: Gertrude Rebecca | G19: 1 | P19: 1 | Q19: 16 | S19: 1 | X19: housemaid | Z19: 1 | AB19: 1 | AD19: leics
A20: PD4 | C20: 1 | D20: Park Drive | E20: Wynn Humphries | F20: Edward | H20: 1 | K20: 1 | Q20: 52 | R20: 1 | X20: Official receiver in bank | Y20: bank of trade | Z20: 1 | AA20: 1 | AD20: manc | AE20: status of emp /worker empty
A21: PD4 | C21: 1 | D21: Park Drive | E21: Brown | F21: Elizabeth | G21: 1 | P21: 1 | Q21: 22 | S21: 1 | X21: domestic servant | Z21: 1 | AB21: 1 | AD21: Derby
A22: TOTAL | B22: 4 | E22: 14 | F22: 19 | G22: =SUM(G3:G21) -> 13 | H22: =SUM(H3:H21) -> 5 | I22: =SUM(I3:I21) -> 1 | J22: =SUM(J3:J21) -> 0 | K22: =SUM(K3:K21) -> 4 | L22: =SUM(L3:L21) -> 2 | M22: =SUM(M3:M21) -> 2 | N22: =SUM(N3:N21) -> 1 | ... AC22: =SUM(AC3:AC21) -> 8 | AD22: 11

Sheet Peveril Drive
A1: House ID | B1: House Name | C1: NO. | D1: Address | E1: Family | F1: Name | G1: W/M/G/B | K1: Relationship to Head of family | Q1: Age | R1: Married/Single/Widow/er | S1: SINGLE | T1: Widow/er | U1: Married yrs | V1: Children born | W1: children living | X1: Personal Occupation | Y1: Industry | Z1: Economic participants | AA1: Employer/worker | AC1: Born | AE1: Note
A2: largest household | B2: smallest household | G2: W | H2: M | I2: G | J2: B | K2: HEAD women head | L2: WIFE | M2: daughter | N2: son | O2: Other | P2: Servant | Q2: If <15=child | R2: Married woman | S2: SINGLE woman | T2: Widow er | AA2: Employer | AB2: worker | AC2: Nottinghamshire | AD2: Other
A3: PeD1 | D3: Peveril Drive | E3: Turpin | F3: John | H3: 1 | K3: 1 | Q3: 62 | R3: 1 | X3: Provision Manuf | Y3: Wholesale Retail | Z3: 1 | AA3: 1 | AD3: Derby
A4: PeD1 | D4: Peveril Drive | E4: Turpin | F4: Isabella | G4: 1 | L4: 1 | Q4: 56 | R4: 1 | U4: 31 | V4: 8 | W4: 7 | AD4: Kirkcudshire
A5: PeD1 | D5: Peveril Drive | E5: Turpin | F5: Heneyer | G5: 1 | N5: 1 | Q5: 28 | S5: 1 | X5: Colliery & mill furnisher | Z5: 1 | AA5: 1 | AC5: 1
A6: PeD1 | D6: Peveril Drive | E6: Turpin | F6: Robert | H6: 1 | N6: 1 | Q6: 25 | S6: 1 | X6: Blouse Manu | Z6: 1 | AB6: 1 | AC6: 1
A7: PeD1 | D7: Peveril Drive | E7: Turpin | F7: Janet Kathleen | G7: 1 | M7: 1 | Q7: 20 | S7: 1 | AC7: 1
A8: PeD1 | D8: Peveril Drive | E8: Turpin | F8: Charles Hugh Kerney | J8: 1 | N8: 1 | Q8: 14 | X8: Scholar | AC8: 1
A9: PeD1 | D9: Peveril Drive | E9: Cowlishow | F9: Helen Ivy | G9: 1 | P9: 1 | Q9: 35 | S9: 1 | X9: General Servant | Z9: 1 | AB9: 1 | AC9: 1
A10: PeD2 | B10: Ivanhoe Lodge | D10: Peveril Drive | E10: Derry | F10: Henry | H10: 1 | K10: 1 | Q10: 47 | R10: 1 | X10: General printer ^ account bk maker | Z10: 1 | AA10: 1 | AD10: Leics
A11: PeD2 | B11: Ivanhoe Lodge | D11: Peveril Drive | E11: Derry | F11: Jessie Ann | G11: 1 | L11: 1 | Q11: 43 | R11: 1 | U11: 15 | V11: 2 | AD11: Liverpool
A12: PeD2 | B12: Ivanhoe Lodge | D12: Peveril Drive | E12: Derry | F12: Hilda Mary | J12: 1 | M12: 1 | Q12: 12 | X12: scholar | AC12: 1
A13: PeD2 | B13: Ivanhoe Lodge | D13: Peveril Drive | E13: Derry | F13: Ida Marie | I13: 1 | M13: 1 | Q13: 9 | X13: scholar | AC13: 1
A14: PeD2 | B14: Ivanhoe Lodge | D14: Peveril Drive | E14: Tonks | F14: Alice | G14: 1 | O14: visitor | Q14: 32 | S14: 1 | X14: lady's companion | Z14: 1 | AB14: 1 | AD14: Shreewbury | AE14: Have put as worker but was not entered on census
A15: PeD3 | B15: Park Dale | D15: Peveril Drive | E15: Woodward | F15: Sydney | H15: 1 | K15: 1 | Q15: 27 | R15: 1 | X15: Lace Manu | Y15: Frank Woodward Co. Ltd | Z15: 1 | AA15: 1 | AC15: 1
A16: PeD3 | B16: Park Dale | D16: Peveril Drive | E16: Woodward | F16: Margaret | G16: 1 | L16: 1 | Q16: 28 | R16: 1 | U16: 3 | V16: 1 | W16: 1 | AC16: 1
A17: PeD3 | B17: Park Dale | D17: Peveril Drive | E17: woodward | F17: Evelyn | I17: 1 | M17: 1 | Q17: 2 | AC17: 1
A18: PeD3 | B18: Park Dale | D18: Peveril Drive | E18: Cole | F18: Ruth | G18: 1 | P18: 1 | Q18: 50 | S18: 1 | X18: Housemaid | Z18: 1 | AB18: 1 | AD18: northants
A19: PeD3 | B19: Park Dale | D19: Peveril Drive | E19: Barker | F19: Mabel | G19: 1 | P19: 1 | Q19: 22 | S19: 1 | X19: Cook | Z19: 1 | AB19: 1 | AC19: 1
A20: PeD3 | B20: Park Dale | D20: Peveril Drive | E20: Galpin | F20: Hilda | G20: 1 | P20: 1 | Q20: 19 | S20: 1 | X20: Nurse | Z20: 1 | AB20: 1 | AC20: 1
A21: PeD4 | B21: Dudley Lodge | D21: Peveril Drive | E21: Spalding | F21: William Arthur | H21: 1 | K21: 1 | Q21: 39 | R21: 1 | X21: Draper | Z21: 1 | AA21: 1 | AD21: London
A22: PeD4 | B22: Dudley Lodge | D22: Peveril Drive | E22: Spalding | F22: Lilian Alice | G22: 1 | L22: 1 | Q22: 38 | R22: 1 | U22: 5 | AD22: London
A23: PeD4 | B23: Dudley Lodge | D23: Peveril Drive | E23: Rogers | F23: Mabel | G23: 1 | P23: 1 | Q23: 22 | S23: 1 | X23: General Servant | Z23: 1 | AB23: 1 | AC23: 1
A24: PeD4 | B24: Dudley Lodge | D24: Peveril Drive | E24: Taylor | F24: Florence Agnes | G24: 1 | P24: 1 | Q24: 18 | S24: 1 | X24: General Servant | Z24: 1 | AB24: 1 | AD24: Derby
A25: PeD5 | B25: Harlech | D25: Peveril Drive | E25: Goodliffe | F25: Johanne | G25: 1 | K25: 1 | Q25: 74 | T25: 1 | V25: 2 | W25: 2 | X25: private means | AD25: Lincs
A26: PeD5 | B26: Harlech | D26: Peveril Drive | E26: Barfield | F26: Sarah Jane | G26: 1 | P26: 1 | S26: 1 | X26: cook | Z26: 1 | AB26: 1 | AD26: Rutland
A27: PeD5 | B27: Harlech | D27: Peveril Drive | E27: Barfield | F27: Mary Rosina | G27: 1 | P27: 1 | S27: 1 | X27: housemaid | Z27: 1 | AB27: 1 | AD27: Rutland
A28: PeD6 | B28: Easdale | D28: Peveril Drive | E28: Polley | F28: Edwin | H28: 1 | K28: 1 | Q28: 35 | R28: 1 | X28: Manager | Y28: Cold Storage | Z28: 1 | AB28: 1 | AD28: Middx
A29: PeD6 | B29: Easdale | D29: Peveril Drive | E29: Polley | F29: Janey | G29: 1 | L29: 1 | Q29: 28 | R29: 1 | U29: 4 | AD29: Staffs
A30: PeD6 | B30: Easdale | D30: Peveril Drive | E30: Jackson | F30: Mary | G30: 1 | P30: 1 | Q30: 15 | S30: 1 | X30: General servant | Z30: 1 | AB30: not entered | AD30: Warwicks
A31: PeD7 | B31: Castle Rock | D31: Peveril Drive | E31: Lloyd | F31: Edward Evans | H31: 1 | K31: 1 | Q31: 68 | R31: 1 | X31: Lead Mauf agent | Z31: 1 | AB31: 1 | AD31: Lancs
A32: PeD7 | B32: Castle Rock | D32: Peveril Drive | E32: Lloyd | F32: Hannah Stanger | G32: 1 | L32: 1 | Q32: 60 | R32: 1 | U32: 14 | AC32: 1
A33: PeD7 | B33: Castle Rock | D33: Peveril Drive | E33: Gill | F33: Ida Maud | G33: 1 | P33: 1 | Q33: 19 | S33: 1 | X33: General Servant | Z33: 1 | AB33: not entered | AD33: London
A34: PeD8 | C34: 3 | D34: Peveril Drive | E34: Burton | F34: Christopher | H34: 1 | K34: 1 | Q34: 47 | R34: 1 | X34: Tailor & Clothier | Z34: 1 | AA34: 1 | AD34: Lincs
A35: PeD8 | C35: 3 | D35: Peveril Drive | E35: Burton | F35: Emily | G35: 1 | L35: 1 | Q35: 48 | R35: 1 | U35: 21 | V35: 4 | W35: 3 | AD35: Suffolk
A36: PeD8 | C36: 3 | D36: Peveril Drive | E36: Burton | F36: Robert Godfrey | H36: 1 | N36: 1 | Q36: 20 | S36: 1 | X36: Clothiers assist | Z36: 1 | AB36: 1 | AC36: 1
A37: PeD8 | C37: 3 | D37: Peveril Drive | E37: Burton | F37: Ivy Kathleen Rose | G37: 1 | M37: 1 | Q37: 19 | S37: 1 | AC37: 1
A38: PeD8 | C38: 3 | D38: Peveril Drive | E38: Burton | F38: Emilie Doreen | I38: 1 | M38: 1 | Q38: 9 | X38: School | AC38: 1
A39: PeD9 | C39: 2 | D39: Peveril Drive | E39: Holgate | F39: Anne Maria | G39: 1 | K39: 1 | Q39: 55 | T39: 1 | V39: 4 | W39: 4 | AD39: Yorks
A40: PeD9 | C40: 2 | D40: Peveril Drive | E40: Holgate | F40: Ernest William | H40: 1 | N40: 1 | Q40: 22 | S40: 1 | X40: Engineering student | AC40: 1
...

Sheet lentonave-dan
A1: House ID | B1: House Name | C1: NO. | D1: Address | E1: Belongs to House | F1: Plot No | G1: Family | H1: Name | I1: Woman | J1: Man | K1: Girl | L1: Boy | M1: Head of family | N1: Wife | O1: Daughter | P1: Son | Q1: Other | R1: Servant | S1: Age | T1: Year of Birth | U1: Married | V1: SINGLE | W1: Widow/er | X1: Years Married | Y1: Personal Occupation | Z1: Industry | AA1: Economic participants | AB1: Employer | AC1: Worker | AD1: Born Nottinghamshire | AE1: Born Other | AF1: Birth County | AG1: Place Town | AH1: Note | AI1: Households | AJ1: Population | AK1: Family | AL1: Servants | AM1: Marital status - Married | AN1: Marital status - Single | AO1: Marital Status - Widow/er | AP1: Employer | AQ1: Worker | AR1: Place of birth - Nottingham | AS1: Place of birth - Oher
A2: largest household | B2: smallest household | E2: Coach House | M2: FEMALE HEAD | S2: If <15=child | U2: Married woman | V2: SINGLE woman | W2: Widow
A3: LA1 | B3: Newlands | C3: 33 | D3: Lenton Avenue | F3: 426 | G3: Wadsworth | H3: Frederic | J3: 1 | M3: 1 | S3: 73 | T3: 1838 | W3: 1 | Y3: Solicitor | Z3: Legal | AA3: 1 | AB3: 1 | AD3: 1 | AF3: Nottinghamshire | AG3: Nottingham
A4: LA1 | B4: Newlands | C4: 33 | D4: Lenton Avenue | F4: 426 | G4: Wadsworth | H4: Mary Lois | I4: 1 | O4: 1 | S4: 33 | T4: 1878 | V4: 1 | AD4: 1 | AF4: Nottinghamshire | AG4: Nottingham
A5: LA1 | B5: Newlands | C5: 33 | D5: Lenton Avenue | F5: 426 | G5: Wilford | H5: Alice Sophia | I5: 1 | R5: 1 | S5: 30 | T5: 1881 | V5: 1 | Y5: Serving Maid | Z5: Domestic | AA5: 1 | AC5: 1 | AE5: 1 | AF5: Leicestershire | AG5: Scalford
A6: LA1 | B6: Newlands | C6: 33 | D6: Lenton Avenue | F6: 426 | G6: Webb | H6: Edith | I6: 1 | R6: 1 | S6: 32 | T6: 1879 | V6: 1 | Y6: Housemaid | Z6: Domestic | AA6: 1 | AC6: 1 | AE6: 1 | AF6: Lincolnshire | AG6: Gedney
A7: LA1 | B7: Newlands | C7: 33 | D7: Lenton Avenue | F7: 426 | G7: Lacey | H7: Mary Ellen | I7: 1 | R7: 1 | S7: 37 | T7: 1874 | V7: 1 | Y7: Cook | Z7: Domestic | AA7: 1 | AC7: 1 | AE7: 1 | AF7: Lincolnshire | AG7: Norton Disney
A8: LA2 | B8: Greylands | C8: 31 | D8: Lenton Avenue | F8: 424 | G8: Lancaster | H8: Annie | I8: 1 | M8: 1 | S8: 50 | T8: 1861 | W8: 1 | Y8: Private Means | AE8: 1 | AF8: Cheshire | AG8: Altringham
A9: LA2 | B9: Greylands | C9: 31 | D9: Lenton Avenue | F9: 424 | G9: Lancaster | H9: Ethel | I9: 1 | O9: 1 | S9: 24 | T9: 1887 | V9: 1 | AD9: 1 | AF9: Nottinghamshire | AG9: Sherwood
A10: LA2 | B10: Greylands | C10: 31 | D10: Lenton Avenue | F10: 424 | G10: Lancaster | H10: Gerald William | J10: 1 | P10: 1 | S10: 22 | T10: 1889 | V10: 1 | Y10: Mining Engineer | Z10: Mining | AA10: 1 | AC10: 1 | AD10: 1 | AF10: Nottinghamshire | AG10: Sherwood
A11: LA2 | B11: Greylands | C11: 31 | D11: Lenton Avenue | F11: 424 | G11: Lancaster | H11: Hannah | I11: 1 | Q11: 1 | S11: 68 | T11: 1843 | V11: 1 | AE11: 1 | AF11: Lancashire | AG11: Patricroft
A12: LA2 | B12: Greylands | C12: 31 | D12: Lenton Avenue | F12: 424 | G12: Harrison | H12: Rachael | I12: 1 | R12: 1 | S12: 23 | T12: 1888 | V12: 1 | Y12: Servant | Z12: Domestic | AA12: 1 | AC12: 1 | AD12: 1 | AF12: Nottinghamshire | AG12: Nuthall
A13: LA2 | B13: Greylands | C13: 31 | D13: Lenton Avenue | F13: 424 | G13: Baylies | H13: Rose | I13: 1 | R13: 1 | S13: 24 | T13: 1887 | V13: 1 | Y13: Servant | Z13: Domestic | AA13: 1 | AC13: 1 | AE13: 1 | AF13: Warwickshire | AG13: Churchover
A14: LA3 | B14: Glenthorpe | C14: 29 | D14: Lenton Avenue | F14: 421 | G14: Sampson | H14: Walter | J14: 1 | M14: 1 | S14: 64 | T14: 1847 | U14: 1 | Y14: Lace Manufacturer | Z14: Lace | AA14: 1 | AB14: 1 | AD14: 1 | AF14: Nottinghamshire | AG14: Lenton
A15: LA3 | B15: Glenthorpe | C15: 29 | D15: Lenton Avenue | F15: 421 | G15: Sampson | H15: Mary | I15: 1 | N15: 1 | S15: 67 | T15: 1844 | U15: 1 | X15: 42 | AD15: 1 | AF15: Nottinghamshire | AG15: Dupart,
A16: LA3 | B16: Glenthorpe | C16: 29 | D16: Lenton Avenue | F16: 421 | G16: Sampson | H16: Albert | J16: 1 | P16: 1 | S16: 36 | T16: 1875 | V16: 1 | Y16: Lace Merchant | Z16: Lace | AA16: 1 | AB16: 1 | AD16: 1 | AF16: Nottinghamshire | AG16: Nottingham
A17: LA3 | B17: Glenthorpe | C17: 29 | D17: Lenton Avenue | F17: 421 | G17: Sampson | H17: Peray | J17: 1 | P17: 1 | S17: 33 | T17: 1878 | V17: 1 | Y17: Lace Manufacturer | Z17: Lace | AA17: 1 | AC17: 1 | AD17: 1 | AF17: Nottinghamshire | AG17: Nottingham
A18: LA3 | B18: Glenthorpe | C18: 29 | D18: Lenton Avenue | F18: 421 | G18: Sampson | H18: Flora | I18: 1 | O18: 1 | S18: 30 | T18: 1881 | V18: 1 | AD18: 1 | AF18: Nottinghamshire | AG18: Nottingham
A19: LA3 | B19: Glenthorpe | C19: 29 | D19: Lenton Avenue | F19: 421 | G19: Sampson | H19: Effie | I19: 1 | O19: 1 | S19: 26 | T19: 1885 | V19: 1 | AD19: 1 | AF19: Nottinghamshire | AG19: Nottingham
A20: LA3 | B20: Glenthorpe | C20: 29 | D20: Lenton Avenue | F20: 421 | G20: Clark | H20: Amy | I20: 1 | R20: 1 | S20: 24 | T20: 1887 | V20: 1 | Y20: Servant | Z20: Domestic | AA20: 1 | AC20: 1 | AD20: 1 | AF20: Nottinghamshire | AG20: Girton
A21: LA3 | B21: Glenthorpe | C21: 29 | D21: Lenton Avenue | F21: 421 | G21: Davis | H21: Agnes | I21: 1 | R21: 1 | S21: 22 | T21: 1889 | V21: 1 | Y21: Servant | Z21: Domestic | AA21: 1 | AC21: 1 | AE21: 1 | AF21: Derbyshire | AG21: South Normanton
A22: LA3 | B22: Glenthorpe | C22: 29 | D22: Lenton Avenue | F22: 421 | G22: Bradshaw | H22: Emma | I22: 1 | R22: 1 | S22: 22 | T22: 1889 | V22: 1 | Y22: Servant | Z22: Domestic | AA22: 1 | AC22: 1 | AE22: 1 | AF22: Derbyshire | AG22: Riddings
A23: LA4 | C23: 27 | D23: Lenton Avenue | F23: 420 | G23: Hauson | H23: Henry | J23: 1 | M23: 1 | S23: 37 | T23: 1874 | U23: 1 | Y23: Solicitor | Z23: Legal | AA23: 1 | AB23: 1 | AD23: 1 | AF23: Nottinghamshire | AG23: Kimberley
A24: LA4 | C24: 27 | D24: Lenton Avenue | F24: 420 | G24: Hauson | H24: Marion | I24: 1 | N24: 1 | S24: 32 | T24: 1879 | U24: 1 | X24: 8 | AE24: 1 | AF24: Middlesex | AG24: Marylebone
A25: LA4 | C25: 27 | D25: Lenton Avenue | F25: 420 | G25: Hauson | H25: Charles Claridge | L25: 1 | P25: 1 | S25: 6 | T25: 1905 | V25: 1 | AD25: 1 | AF25: Nottinghamshire | AG25: Southwell,
A26: LA4 | C26: 27 | D26: Lenton Avenue | F26: 420 | G26: Hauson | H26: Henry Norman | L26: 1 | P26: 1 | S26: 1 | T26: 1910 | V26: 1 | AD26: 1 | AF26: Nottinghamshire | AG26: Nottingham
A27: LA4 | C27: 27 | D27: Lenton Avenue | F27: 420 | G27: Green | H27: Maud Hannah | I27: 1 | R27: 1 | S27: 32 | T27: 1879 | V27: 1 | Y27: Cook | Z27: Domestic | AA27: 1 | AC27: 1 | AE27: 1 | AF27: Essex | AG27: Essex
A28: LA4 | C28: 27 | D28: Lenton Avenue | F28: 420 | G28: Dudgeon | H28: Margaret | I28: 1 | R28: 1 | S28: 22 | T28: 1889 | V28: 1 | Y28: Housemaid | Z28: Domestic | AA28: 1 | AC28: 1 | AE28: 1 | AF28: Staffordhsire | AG28: Burton upon Trent
A29: LA5 | B29: Arlington House | C29: 25 | D29: Lenton Avenue | F29: 419 | G29: Crewdson | H29: Henry | J29: 1 | M29: 1 | S29: 58 | T29: 1853 | U29: 1 | Y29: Solicitor | Z29: Legal | AA29: 1 | AB29: 1 | AE29: 1 | AF29: Westmoreland | AG29: Kendal,
A30: LA5 | B30: Arlington House | C30: 25 | D30: Lenton Avenue | F30: 419 | G30: Creoom-Crewdson | H30: Margaret | I30: 1 | N30: 1 | S30: 52 | T30: 1859 | U30: 1 | X30: 28 | AE30: 1 | AF30: Lanerkshire | AG30: Glasgow,
A31: LA5 | B31: Arlington House | C31: 25 | D31: Lenton Avenue | F31: 419 | G31: Goulty | H31: Mary | I31: 1 | R31: 1 | S31: 28 | T31: 1883 | V31: 1 | Y31: Cook | Z31: Domestic | AA31: 1 | AC31: 1 | AD31: 1 | AF31: Nottinghamshire | AG31: Aslockton
A32: LA5 | B32: Arlington House | C32: 25 | D32: Lenton Avenue | F32: 419 | G32: Ogden | H32: Lucy | I32: 1 | R32: 1 | S32: 29 | T32: 1882 | V32: 1 | Y32: Parlor Maid | Z32: Domestic | AA32: 1 | AC32: 1 | AE32: 1 | AF32: Lincolnshire | AG32: Digby
A33: LA5 | B33: Arlington House | C33: 25 | D33: Lenton Avenue | F33: 419 | G33: Lawrence | H33: Lilian | I33: 1 | R33: 1 | S33: 35 | T33: 1876 | V33: 1 | Y33: Maid | Z33: Domestic | AA33: 1 | AC33: 1 | AD33: 1 | AF33: Nottinghamshire | AG33: Nottingham
A34: LA5 | B34: Arlington House | C34: 25 | D34: Lenton Avenue | F34: 419 | G34: Bird | H34: Gerturde Fanny | I34: 1 | R34: 1 | S34: 19 | T34: 1892 | V34: 1 | Y34: House Maid | Z34: Domestic | AA34: 1 | AC34: 1 | AE34: 1 | AF34: Leicestershire | AG34: Stathern
A35: LA6 | C35: 14 | D35: Lenton Avenue | E35: 29 | F35: 417 | G35: Gamble | H35: John George | J35: 1 | M35: 1 | S35: 46 | T35: 1865 | U35: 1 | Y35: Horse Depository Foreman | Z35: Domestic | AA35: 1 | AC35: 1 | AD35: 1 | AF35: Nottinghamshire | AG35: Nottingham
A36: LA6 | C36: 14 | D36: Lenton Avenue | E36: 29 | F36: 417 | G36: Gamble | H36: Elizabeth Ann | I36: 1 | N36: 1 | S36: 47 | T36: 1864 | U36: 1 | X36: 26 | AD36: 1 | AF36: Nottinghamshire | AG36: Nottingham
A37: LA6 | C37: 14 | D37: Lenton Avenue | E37: 29 | F37: 417 | G37: Gamble | H37: Edith | I37: 1 | O37: 1 | S37: 25 | T37: 1886 | V37: 1 | Y37: Elementary School Teacher | Z37: Education | AA37: 1 | AC37: 1 | AD37: 1 | AF37: Nottinghamshire | AG37: Nottingham
A38: LA6 | C38: 14 | D38: Lenton Avenue | E38: 29 | F38: 417 | G38: Gamble | H38: Irene | K38: 1 | O38: 1 | S38: 11 | T38: 1900 | V38: 1 | Y38: Attends School | AD38: 1 | AF38: Nottinghamshire | AG38: Nottingham
A39: LA7 | C39: 12 | D39: Lenton Avenue | E39: 29 | F39: 417 | G39: Rawson | H39: Henry | J39: 1 | M39: 1 | S39: 57 | T39: 1854 | U39: 1 | Y39: Gardener | Z39: Domestic | AA39: 1 | AC39: 1 | AD39: 1 | AF39: Nottinghamshire | AG39: Normanton
A40: LA7 | C40: 12 | D40: Lenton Avenue | E40: 29 | F40: 417 | G40: Rawson | H40: Elizabeth | J40: 1 | N40: 1 | S40: 55 | T40: 1856 | U40: 1 | X40: 34 | AD40: 1 | AF40: Nottinghamshire | AG40: Blidworth
...

Sheet Clumber rd W dan
A1: House ID | B1: House Name | C1: NO. | D1: Address | E1: Belongs to House | F1: Plot No | G1: Family | H1: Name | I1: Woman | J1: Man | K1: Girl | L1: Boy | M1: Head of family | N1: Wife | O1: Daughter | P1: Son | Q1: Other | R1: Servant | S1: Age | T1: Year of Birth | U1: Married | V1: SINGLE | W1: Widow/er | X1: Years Married | Y1: Personal Occupation | Z1: Industry | AA1: Economic participants | AB1: Employer | AC1: Worker | AD1: Born Nottinghamshire | AE1: Born Other | AF1: Birth County | AG1: Place Town | AH1: Note | AI1: Households | AJ1: Population | AK1: Family | AL1: Servants | AM1: Marital status - Married | AN1: Marital status - Single | AO1: Marital Status - Widow/er | AP1: Employer | AQ1: Worker | AR1: Place of birth - Nottingham | AS1: Place of birth - Oher
A2: largest household | B2: smallest household | E2: Coach House | M2: FEMALE HEAD | S2: If <15=child | U2: Married woman | V2: SINGLE woman | W2: Widow
A3: CRW1 | B3: Felixstowe | D3: Clumber Road West | F3: 570 | G3: Dowson | H3: William Enfield | J3: 1 | M3: 1 | S3: 46 | T3: 1865 | U3: 1 | Y3: Lace Manufacturer | Z3: Lace | AA3: 1 | AB3: 1 | AD3: 1 | AF3: Nottinghamshire | AG3: Nottingham
A4: CRW1 | B4: Felixstowe | D4: Clumber Road West | F4: 570 | G4: Dowson | H4: Helena Brownsword | I4: 1 | N4: 1 | S4: 44 | T4: 1867 | U4: 1 | X4: 16 | Y4: Secretary | Z4: Sufferage Soc | AA4: 1 | AC4: 1 | AD4: 1 | AF4: Nottinghamshire | AG4: Nottingham
A5: CRW1 | B5: Felixstowe | D5: Clumber Road West | F5: 570 | G5: Jackson | H5: Alice Maud | I5: 1 | R5: 1 | S5: 37 | T5: 1874 | V5: 1 | Y5: Cook | Z5: Domestic | AA5: 1 | AC5: 1 | AE5: 1 | AF5: Hampshire | AG5: Portsmouth
A6: CRW1 | B6: Felixstowe | D6: Clumber Road West | F6: 570 | G6: Underwood | H6: Caroline | I6: 1 | R6: 1 | S6: 30 | T6: 1881 | V6: 1 | Y6: Parlour Maid | Z6: Domestic | AA6: 1 | AC6: 1 | AE6: 1 | AF6: Warwickshire | AG6: Leamington Spa
A7: CRW1 | B7: Felixstowe | D7: Clumber Road West | F7: 570 | G7: Greenway | H7: Elsie | I7: 1 | R7: 1 | S7: 18 | T7: 1893 | V7: 1 | Y7: House Maid | Z7: Domestic | AA7: 1 | AC7: 1 | AE7: 1 | AF7: Warwickshire | AG7: Birmingham
A8: CRW2 | B8: Linden House | D8: Clumber Road West | F8: 609 | G8: Lamb | H8: John William | J8: 1 | M8: 1 | S8: 74 | T8: 1837 | V8: 1 | Y8: Hosiery Manufacturer | Z8: Hosiery | AA8: 1 | AB8: 1 | AD8: 1 | AF8: Nottinghamshire | AG8: Nottingham
A9: CRW2 | B9: Linden House | D9: Clumber Road West | F9: 609 | G9: Lamb | H9: Charles Thomas | J9: 1 | Q9: 1 | S9: 67 | T9: 1844 | V9: 1 | Y9: Suit Fitter | Z9: Tailoring | AA9: 1 | AB9: 1 | AD9: 1 | AF9: Nottinghamshire | AG9: Nottingham | AH9: Brother
A10: CRW2 | B10: Linden House | D10: Clumber Road West | F10: 609 | G10: Lamb | H10: Caroline Sarah | I10: 1 | Q10: 1 | S10: 69 | T10: 1842 | V10: 1 | AD10: 1 | AF10: Nottinghamshire | AG10: Nottingham | AH10: Sister
A11: CRW2 | B11: Linden House | D11: Clumber Road West | F11: 609 | G11: Hill | H11: Mary Elizabeth | I11: 1 | R11: 1 | S11: 36 | T11: 1875 | V11: 1 | Y11: Servant | Z11: Domestic | AA11: 1 | AC11: 1 | AE11: 1 | AF11: Derbyshire | AG11: Ticknall
A12: CRW2 | B12: Linden House | D12: Clumber Road West | F12: 609 | G12: Hill | H12: Gertrude | I12: 1 | R12: 1 | S12: 30 | T12: 1881 | V12: 1 | Y12: Servant | Z12: Domestic | AA12: 1 | AC12: 1 | AE12: 1 | AF12: Derbyshire | AG12: Ticknall
A13: CRW3 | B13: Holly Lodge | D13: Clumber Road West | F13: 572 | G13: Berrey | H13: J Edmund | J13: 1 | M13: 1 | S13: 67 | T13: 1884 | W13: 1 | Y13: Lace Manufacturer | Z13: Lace | AA13: 1 | AB13: 1 | AD13: 1 | AF13: Nottinghamshire | AG13: Nottingham
A14: CRW3 | B14: Holly Lodge | D14: Clumber Road West | F14: 572 | G14: Berrey | H14: Mabel | I14: 1 | O14: 1 | S14: 25 | T14: 1886 | V14: 1 | AD14: 1 | AF14: Nottinghamshire | AG14: Nottingham
A15: CRW3 | B15: Holly Lodge | D15: Clumber Road West | F15: 572 | G15: Dexter | H15: Letitia | I15: 1 | R15: 1 | S15: 60 | T15: 1851 | V15: 1 | Y15: Housekeeper | Z15: Domestic | AA15: 1 | AC15: 1 | AD15: 1 | AF15: Nottinghamshire | AG15: Nottingham
A16: CRW3 | B16: Holly Lodge | D16: Clumber Road West | F16: 572 | G16: Dexter | H16: Alice | I16: 1 | R16: 1 | S16: 43 | T16: 1868 | V16: 1 | Y16: Cook | Z16: Domestic | AA16: 1 | AC16: 1 | AE16: 1 | AF16: Derbyshire | AG16: Kilburn
A17: CRW3 | B17: Holly Lodge | D17: Clumber Road West | F17: 572 | G17: Hicks | H17: Edith | I17: 1 | R17: 1 | S17: 36 | T17: 1875 | V17: 1 | Y17: Housemaid | Z17: Domestic | AA17: 1 | AC17: 1 | AE17: 1 | AF17: Lincolnshire | AG17: Lincoln
A18: TOTAL | D18: 17 | G18: 9 | H18: 15 | I18: =SUM(I3:I17) -> 11 | J18: =SUM(J3:J17) -> 4 | K18: =SUM(K3:K17) -> 0 | L18: =SUM(L3:L17) -> 0 | M18: =SUM(M3:M17) -> 3 | N18: =SUM(N3:N17) -> 1 | O18: =SUM(O3:O17) -> 1 | P18: =SUM(P3:P17) -> 0 | ... S18: =SUM(S3:S17) -> 682 | U18: =SUM(U3:U17) -> 2 | V18: =SUM(V3:V17) -> 12 | W18: =SUM(W3:W17) -> 1 | X18: =SUM(X3:X17) -> 16 | AA18: =SUM(AA3:AA17) -> 13 | AB18: =SUM(AB3:AB17) -> 4 | AC18: =SUM(AC3:AC17) -> 9 | AD18: =SUM(AD3:AD17) -> 8 | AE18: =SUM(AE3:AE17) -> 7

Sheet maxtoke rd dan
A1: House ID | B1: House Name | C1: NO. | D1: Address | E1: Belongs to House | F1: Plot No | G1: Family | H1: Name | I1: Woman | J1: Man | K1: Girl | L1: Boy | M1: Head of family | N1: Wife | O1: Daughter | P1: Son | Q1: Other | R1: Servant | S1: Age | T1: Year of Birth | U1: Married | V1: SINGLE | W1: Widow/er | X1: Years Married | Y1: Personal Occupation | Z1: Industry | AA1: Economic participants | AB1: Employer | AC1: Worker | AD1: Born Nottinghamshire | AE1: Born Other | AF1: Birth County | AG1: Place Town | AH1: Note | AI1: Households | AJ1: Population | AK1: Family | AL1: Servants | AM1: Marital status - Married | AN1: Marital status - Single | AO1: Marital Status - Widow/er | AP1: Employer | AQ1: Worker | AR1: Place of birth - Nottingham | AS1: Place of birth - Oher
A2: largest household | B2: smallest household | E2: Coach House | M2: FEMALE HEAD | S2: If <15=child | U2: Married woman | V2: SINGLE woman | W2: Widow
A3: MR1 | B3: Stowe House | C3: 6 | D3: Maxtoke Road | F3: 568 | G3: Hesse | H3: Marie Augustine | I3: 1 | M3: 1 | S3: 60 | T3: 1851 | W3: 1 | AE3: 1 | AF3: Belgium | AG3: Brussells
A4: MR1 | B4: Stowe House | C4: 6 | D4: Maxtoke Road | F4: 568 | G4: Reid | H4: May Catherine | I4: 1 | Q4: 1 | S4: 28 | T4: 1883 | V4: 1 | Y4: Ladies Companion | Z4: Domestic | AA4: 1 | AC4: 1 | AE4: 1 | AF4: Surrey | AG4: Croydon
A5: MR1 | B5: Stowe House | C5: 6 | D5: Maxtoke Road | F5: 568 | G5: Whittaker | H5: Gertrude | I5: 1 | R5: 1 | S5: 29 | T5: 1882 | V5: 1 | Y5: Servant | Z5: Domestic | AA5: 1 | AC5: 1 | AD5: 1 | AF5: Nottinghamshire | AG5: Gamston
A6: MR1 | B6: Stowe House | C6: 6 | D6: Maxtoke Road | F6: 568 | G6: Whitehead | H6: Emily Julia | I6: 1 | R6: 1 | S6: 17 | T6: 1894 | V6: 1 | Y6: Servant | Z6: Domestic | AA6: 1 | AC6: 1 | AD6: 1 | AF6: Nottinghamshire | AG6: Nottingham
A7: MR2 | B7: Burton House | C7: 1 | D7: Maxtoke Road | F7: 608 | G7: Ransom | H7: Doley Scott | J7: 1 | M7: 1 | S7: 48 | T7: 1863 | U7: 1 | Y7: Solicitor | Z7: Legal | AA7: 1 | AB7: 1 | AD7: 1 | AF7: Nottinghamshire | AG7: Nottingham
A8: MR2 | B8: Burton House | C8: 1 | D8: Maxtoke Road | F8: 608 | G8: Ransom | H8: Helen Winifred | I8: 1 | N8: 1 | S8: 37 | T8: 1874 | U8: 1 | AD8: 1 | AF8: Nottinghamshire | AG8: Nottingham
A9: MR2 | B9: Burton House | C9: 1 | D9: Maxtoke Road | F9: 608 | G9: Ransom | H9: Helen Judith | K9: 1 | O9: 1 | S9: 13 | T9: 1898 | V9: 1 | Y9: Attends School | AD9: 1 | AF9: Nottinghamshire | AG9: Nottingham
A10: MR2 | B10: Burton House | C10: 1 | D10: Maxtoke Road | F10: 608 | G10: Ransom | H10: Elizabeth | K10: 1 | O10: 1 | S10: 11 | T10: 1900 | V10: 1 | Y10: Attends School | AD10: 1 | AF10: Nottinghamshire | AG10: Nottingham
A11: MR2 | B11: Burton House | C11: 1 | D11: Maxtoke Road | F11: 608 | G11: Ransom | H11: Winifred Mary | K11: 1 | O11: 1 | S11: 9 | T11: 1902 | V11: 1 | AD11: 1 | AF11: Nottinghamshire | AG11: Nottingham
A12: MR2 | B12: Burton House | C12: 1 | D12: Maxtoke Road | F12: 608 | G12: Ransom | H12: Dorothy Byrom | K12: 1 | O12: 1 | S12: 2 | T12: 1909 | V12: 1 | AD12: 1 | AF12: Nottinghamshire | AG12: Nottingham
A13: MR2 | B13: Burton House | C13: 1 | D13: Maxtoke Road | F13: 608 | G13: Ransom | H13: Charles Herbert Flower | L13: 1 | P13: 1 | S13: 0.4 | T13: 1911 | V13: 1 | AD13: 1 | AF13: Nottinghamshire | AG13: Nottingham
